Workbook

Sheet 汇总
B2: 机器人预算与选型汇总表（2台 · 同配置）
B3: 按淘宝订单实付款口径（含运费） · 币种：人民币元 · 制表日期 2026-10-18
B4: 序号 | C4: 类别 | D4: 包含内容 | E4: 实付金额（元） | F4: 占已实付比例
B5: 1 | C5: 主控与调试 | D5: STM32F103C8T6核心板 ×3 | E5: =SUMIF(预算明细!$C$5:$C$39,C5,预算明细!$I$5:$I$39) -> 26.45 | F5: =IFERROR(E5/$E$17,0) -> 0.06396769
B6: 2 | C6: 舵机 | D6: MG995 ×2、SG90 ×6 | E6: =SUMIF(预算明细!$C$5:$C$39,C6,预算明细!$I$5:$I$39) -> 62.3 | F6: =IFERROR(E6/$E$17,0) -> 0.1506687
B7: 3 | C7: 遥控 | D7: PS2无线手柄 ×2 | E7: =SUMIF(预算明细!$C$5:$C$39,C7,预算明细!$I$5:$I$39) -> 81.96 | F7: =IFERROR(E7/$E$17,0) -> 0.19821519
B8: 4 | C8: 电机与驱动 | D8: TT马达 ×8、DRV8833 ×4、麦轮套件 ×2 | E8: =SUMIF(预算明细!$C$5:$C$39,C8,预算明细!$I$5:$I$39) -> 103.18 | F8: =IFERROR(E8/$E$17,0) -> 0.24953445
B9: 5 | C9: 底盘 | D9: 4轮金属折弯底盘 ×2 | E9: =SUMIF(预算明细!$C$5:$C$39,C9,预算明细!$I$5:$I$39) -> 22.18 | F9: =IFERROR(E9/$E$17,0) -> 0.053640959
B10: 6 | C10: 电源 | D10: 降压模块 ×2、18650电池 ×4节、电池盒 ×2 | E10: =SUMIF(预算明细!$C$5:$C$39,C10,预算明细!$I$5:$I$39) -> 34.98 | F10: =IFERROR(E10/$E$17,0) -> 0.084596967
B11: 7 | C11: 面包板与连接线 | D11: 面包板 ×1、杜邦线 ×4束 | E11: =SUMIF(预算明细!$C$5:$C$39,C11,预算明细!$I$5:$I$39) -> 14.68 | F11: =IFERROR(E11/$E$17,0) -> 0.035502672
B12: 8 | C12: 无线继电器 | D12: 无线遥控开关 ×2套 | E12: =SUMIF(预算明细!$C$5:$C$39,C12,预算明细!$I$5:$I$39) -> 27.6 | F12: =IFERROR(E12/$E$17,0) -> 0.066748894
B13: 9 | C13: 运费 | D13: 2笔订单快递费 | E13: =SUMIF(预算明细!$C$5:$C$39,C13,预算明细!$I$5:$I$39) -> 6.8 | F13: =IFERROR(E13/$E$17,0) -> 0.01644538
B14: 10 | C14: 尾差 | D14: 2笔订单价格精度尾差 | E14: =SUMIF(预算明细!$C$5:$C$39,C14,预算明细!$I$5:$I$39) -> 0.05 | F14: =IFERROR(E14/$E$17,0) -> 0.00012092191
B15: 11 | C15: 表外·紧固件与结构件 | D15: 螺丝/螺母/垫片/铜柱等 | E15: =SUMIF(预算明细!$C$5:$C$39,C15,预算明细!$I$5:$I$39) -> 24.68 | F15: =IFERROR(E15/$E$17,0) -> 0.059687054
B16: 12 | C16: 表外·连接器 | D16: 排针、排母 | E16: =SUMIF(预算明细!$C$5:$C$39,C16,预算明细!$I$5:$I$39) -> 8.63 | F16: =IFERROR(E16/$E$17,0) -> 0.020871121
C17: 合计 | E17: =SUM(E5:E16) -> 413.49
B19: 注：① 已实付合计含快递运费6.80元与店铺价格精度尾差0.05元；② 无线继电器按官方说明为通过中期测评后购置，本队已提前购入；③ 表外紧固件、垫片、铜柱、排针/排母属规则允许的紧固件/粘合剂/自制件范畴；④ 金额均取淘宝订单“实付款”，明细见“预算明细”与“订单记录”。

Sheet 预算明细
B2: 采购预算明细表（按实付款）
B3: 两台机器人合计采购量（同配置）；小计=单价×数量；实付口径含运费与店铺尾差
B4: 序号 | C4: 类别 | D4: 物品名称 | E4: 款式/规格 | F4: 单台数量 | G4: 已购数量 | H4: 单价（元） | I4: 小计（元） | J4: 采购店铺 | K4: 下单日期 | L4: 备注
B5: 1 | C5: 主控与调试 | D5: STM32F103C8T6核心板 | E5: Micro_焊接 | F5: 1 | G5: 2 | H5: 9.23 | I5: =H5*G5 -> 18.46 | J5: 深圳市优信电子科技有限公司 | K5: 2026-09-13 | L5: 每台1块
B6: 2 | C6: 主控与调试 | D6: STM32F103C8T6核心板 | E6: Micro_焊接 | F6: — | G6: 1 | H6: 7.99 | I6: =H6*G6 -> 7.99 | J6: 深圳市优信电子科技有限公司 | K6: 2026-10-10 | L6: 备用1块（补购）
B7: 3 | C7: 舵机 | D7: MG995舵机 | E7: 180度 铁+铜齿轮 | F7: 1 | G7: 2 | H7: 14.39 | I7: =H7*G7 -> 28.78 | J7: 深圳市优信电子科技有限公司 | K7: 2026-09-13 | L7: 每台1个，主执行关节
B8: 4 | C8: 舵机 | D8: SG90舵机 | E8: 180度 | F8: 2 | G8: 4 | H8: 5.85 | I8: =H8*G8 -> 23.4 | J8: 深圳市优信电子科技有限公司 | K8: 2026-09-13 | L8: 每台2个
B9: 5 | C9: 舵机 | D9: SG90舵机 | E9: 180度 | F9: — | G9: 2 | H9: 5.06 | I9: =H9*G9 -> 10.12 | J9: 深圳市优信电子科技有限公司 | K9: 2026-10-10 | L9: 备用2个（补购）
B10: 6 | C10: 遥控 | D10: PS2无线手柄 | E10: 锁定款+直插转接板（排针） | F10: 1套 | G10: 2 | H10: 40.98 | I10: =H10*G10 -> 81.96 | J10: 塔克创新品牌店 | K10: 2026-09-13 | L10: 官方指定可对频锁定款；本单运费3.80元已另列
B11: 7 | C11: 电机与驱动 | D11: TT马达 | E11: 单轴1比48 | F11: 4 | G11: 8 | H11: 2.83 | I11: =H11*G11 -> 22.64 | J11: RunesKee工业旗舰店 | K11: 2026-09-13 | L11: 每台4个，四轮驱动
B12: 8 | C12: 电机与驱动 | D12: DRV8833电机驱动模块 | E12: 红板 | F12: 2 | G12: 4 | H12: 2.03 | I12: =H12*G12 -> 8.12 | J12: 深圳市优信电子科技有限公司 | K12: 2026-09-13 | L12: 每台2块，每块双H桥驱动2路电机
B13: 9 | C13: 电机与驱动 | D13: 麦克纳姆轮 | E13: 60mm 黄色 一套4个（含TT马达联轴器） | F13: 1套 | G13: 2 | H13: 36.21 | I13: =H13*G13 -> 72.42 | J13: 塔克创新品牌店 | K13: 2026-09-13 | L13: 每台1套；本单运费3.80元已另列
B14: 10 | C14: 底盘 | D14: 小车底盘 | E14: 4轮金属折弯板（一体带马达孔） | F14: 1 | G14: 2 | H14: 11.09 | I14: =H14*G14 -> 22.18 | J14: 欣薇电子企业店 | K14: 2026-09-13 | L14: 每台1块；本单运费3.00元已另列
B15: 11 | C15: 电源 | D15: DC-DC降压模块 | E15: Mini 5V 黑板 | F15: 1 | G15: 2 | H15: 2.07 | I15: =H15*G15 -> 4.14 | J15: 深圳市优信电子科技有限公司 | K15: 2026-09-13 | L15: 每台1块，输出5V供核心板与舵机
B16: 12 | C16: 电源 | D16: 18650电池 | E16: 9250mAh 尖头（两节装） | F16: 2节 | G16: 1 | H16: 19.89 | I16: =H16*G16 -> 19.89 | J16: EMPERORTIGER旗舰店 | K16: 2026-09-13 | L16: 一单两节装，含双槽充电器；每台2节
... B19: 15 | C19: 面包板与连接线 | D19: 面包板 | E19: MB-102 830孔 | F19: 1 | G19: 1 | H19: 3.48 | I19: =H19*G19 -> 3.48 | J19: 深圳市优信电子科技有限公司 | K19: 2026-09-13 | L19: 官方清单共2个，尚差1个
B20: 16 | C20: 面包板与连接线 | D20: 杜邦线 | E20: 10CM 公对公 40P | F20: 1束 | G20: 1 | H20: 2.66 | I20: =H20*G20 -> 2.66 | J20: 深圳市优信电子科技有限公司 | K20: 2026-09-13
B21: 17 | C21: 面包板与连接线 | D21: 杜邦线 | E21: 10CM 公对母 40P | F21: 1束 | G21: 1 | H21: 2.36 | I21: =H21*G21 -> 2.36 | J21: 深圳市优信电子科技有限公司 | K21: 2026-09-13
B22: 18 | C22: 面包板与连接线 | D22: 杜邦线 | E22: 10CM 母对母 40P | F22: 1束 | G22: 1 | H22: 2.07 | I22: =H22*G22 -> 2.07 | J22: 深圳市优信电子科技有限公司 | K22: 2026-09-13
B23: 19 | C23: 面包板与连接线 | D23: 杜邦线 | E23: 21CM 公对公 无壳全铜 | F23: — | G23: 1 | H23: 4.11 | I23: =H23*G23 -> 4.11 | J23: 深圳市优信电子科技有限公司 | K23: 2026-09-13 | L23: 清单外加长线
B24: 20 | C24: 无线继电器 | D24: 无线继电器 | E24: DC5-24V 1个接收器+1个单键 | F24: 1套 | G24: 2 | H24: 13.8 | I24: =H24*G24 -> 27.6 | J24: 乐柠萌科技企业店 | K24: 2026-09-21 | L24: 每台1套；官方说明为通过中期测评后购置
B25: 21 | C25: 运费 | D25: 快递运费 | E25: 欣薇电子底盘订单 | F25: — | G25: 1 | H25: 3 | I25: =H25*G25 -> 3 | J25: 欣薇电子企业店 | K25: 2026-09-13
B26: 22 | C26: 运费 | D26: 快递运费 | E26: 塔克创新手柄+麦轮订单 | F26: — | G26: 1 | H26: 3.8 | I26: =H26*G26 -> 3.8 | J26: 塔克创新品牌店 | K26: 2026-09-13
B27: 23 | C27: 表外·紧固件与结构件 | D27: 不锈钢螺母 M3 | E27: 304 100粒 | F27: — | G27: 2 | H27: 2.05 | I27: =H27*G27 -> 4.1 | J27: 佰瑞特官方旗舰店 | K27: 2026-10-06
B28: 24 | C28: 表外·紧固件与结构件 | D28: 不锈钢螺母 M2 | E28: 304 100粒 | F28: — | G28: 1 | H28: 2.88 | I28: =H28*G28 -> 2.88 | J28: 佰瑞特官方旗舰店 | K28: 2026-10-06
B29: 25 | C29: 表外·紧固件与结构件 | D29: 内六角螺丝 M3×5 | E29: 12.9级 100个 全牙 | F29: — | G29: 1 | H29: 2.81 | I29: =H29*G29 -> 2.81 | J29: 佰瑞特官方旗舰店 | K29: 2026-10-06
B30: 26 | C30: 表外·紧固件与结构件 | D30: 内六角螺丝 M3×8 | E30: 12.9级 100个 全牙 | F30: — | G30: 1 | H30: 2.82 | I30: =H30*G30 -> 2.82 | J30: 佰瑞特官方旗舰店 | K30: 2026-10-06
B31: 27 | C31: 表外·紧固件与结构件 | D31: 内六角螺丝 M2×8 | E31: 12.9级 100个 全牙 | F31: — | G31: 1 | H31: 2.63 | I31: =H31*G31 -> 2.63 | J31: 佰瑞特官方旗舰店 | K31: 2026-10-06
B32: 28 | C32: 表外·紧固件与结构件 | D32: 十字盘头螺丝 M3×25 | E32: 镀镍带垫 100个 | F32: — | G32: 1 | H32: 1.1 | I32: =H32*G32 -> 1.1 | J32: 海锐新电子商城 | K32: 2026-10-10
B33: 29 | C33: 表外·紧固件与结构件 | D33: 平垫片 M3×6×0.8 | E33: 304不锈钢 100颗 | F33: — | G33: 1 | H33: 1.34 | I33: =H33*G33 -> 1.34 | J33: 嘉耐特官方旗舰店 | K33: 2026-10-06
B34: 30 | C34: 表外·紧固件与结构件 | D34: 六角铜柱 M3×10+4 | E34: 单头 40个 | F34: — | G34: 1 | H34: 3.84 | I34: =H34*G34 -> 3.84 | J34: 佰瑞特官方旗舰店 | K34: 2026-10-06
B35: 31 | C35: 表外·紧固件与结构件 | D35: 不锈钢螺母 M3 | E35: 304 200只 | F35: — | G35: 1 | H35: 3.16 | I35: =H35*G35 -> 3.16 | J35: 固万基官方旗舰店 | K35: 2026-10-01
B36: 32 | C36: 表外·连接器 | D36: 单排针 | E36: 2.54mm 5P 20条 | F36: — | G36: 1 | H36: 2.3 | I36: =H36*G36 -> 2.3 | J36: 晶凝峰芯达专卖店 | K36: 2026-09-18 | L36: 手柄转接板等焊接用
B37: 33 | C37: 表外·连接器 | D37: 单排母 | E37: 2.54mm 1×10P 塑高5.7 10条 | F37: — | G37: 1 | H37: 3.63 | I37: =H37*G37 -> 3.63 | J37: 晶凝峰芯达专卖店 | K37: 2026-09-18
B38: 34 | C38: 表外·连接器 | D38: 单排母 | E38: 2.54mm 1×4P 20只 | F38: — | G38: 1 | H38: 2.7 | I38: =H38*G38 -> 2.7 | J38: 深圳市英莱利科技有限公司 | K38: 2026-09-27
B39: 35 | C39: 尾差 | D39: 订单尾差 | E39: 塔克单0.01元 + 优信单0.04元 | F39: — | I39: 0.05 | J39: — | K39: — | L39: 店铺价格精度/凑单优惠所致，小计为直接给定值
C40: 实付合计（14笔订单，含运费与尾差） | I40: =SUM(I5:I39) -> 413.49
B42: 三、待购 / 建议补购（尚未实际支出，不计入上方实付合计）
B43: 待1 | C43: 待购·必买 | D43: ST-LINK V2仿真器 | E43: ST-LINK V2 可升级版 | G43: 1 | H43: 12.42 | I43: =H43*G43 -> 12.42 | L43: 官方物资表内参考价；截图订单中未见购买记录，固件烧录必需
B44: 待2 | C44: 待购·建议补购 | D44: 面包板 | E44: MB-102 830孔 | G44: 1 | H44: 3.48 | I44: =H44*G44 -> 3.48 | L44: 官方清单共2个，已购1个；按已购同款单价估算
...

Sheet 选型配置
B2: 每台选型配置表（两台配置相同）
B3: “单台数量”为一台机器人所需，两台合计=单台数量×2；“已购数量”含备用件
B4: 序号 | C4: 功能部位 | D4: 选型（款式/规格） | E4: 单台数量 | F4: 两台合计 | G4: 已购数量 | H4: 备货情况 | I4: 选型说明
B5: 1 | C5: 主控 | D5: STM32F103C8T6核心板（Micro_焊接） | E5: 1 | F5: 2 | G5: 3 | H5: 已备足（含备用1块） | I5: ARM Cortex-M3 主控，两台同配置，负责运动控制与遥控指令解算
B6: 2 | C6: 遥控 | D6: PS2无线手柄（可对频锁定款+直插转接板） | E6: 1套 | F6: 2套 | G6: 2套 | H6: 已备足 | I6: 官方指定可对频锁定款，避免同频干扰导致失控
B7: 3 | C7: 执行机构-大扭矩 | D7: MG995舵机（180度 铁+铜齿轮） | E7: 1 | F7: 2 | G7: 2 | H7: 已备足 | I7: 金属齿轮大扭矩舵机，用于负载较大的执行关节
B8: 4 | C8: 执行机构-轻型 | D8: SG90舵机（180度） | E8: 2 | F8: 4 | G8: 6 | H8: 已备足（含备用2个） | I8: 轻量舵机，用于夹取等小型动作
B9: 5 | C9: 电机驱动 | D9: DRV8833驱动模块（红板） | E9: 2 | F9: 4 | G9: 4 | H9: 已备足 | I9: 双H桥芯片，每块驱动2个TT电机，共4路
B10: 6 | C10: 行走电机 | D10: TT马达（单轴1:48减速） | E10: 4 | F10: 8 | G10: 8 | H10: 已备足 | I10: DC3-6V直流减速电机，四轮驱动
B11: 7 | C11: 轮组 | D11: 麦克纳姆轮60mm（一套4个，含联轴器） | E11: 1套 | F11: 2套 | G11: 2套 | H11: 已备足 | I11: 支持横移、斜向与原地转向
B12: 8 | C12: 底盘 | D12: 4轮金属折弯底盘（一体带马达孔） | E12: 1 | F12: 2 | G12: 2 | H12: 已备足 | I12: 约25.5×15cm金属底板，整车安装平台
B13: 9 | C13: 电池 | D13: 18650锂电池（9250mAh 尖头） | E13: 2节 | F13: 4节 | G13: 3节 | H13: 尚缺1节（建议补购） | I13: 经电池盒串联约7.4V，为电机与驱动供电
B14: 10 | C14: 电池盒 | D14: 18650两节带线电池盒 | E14: 1 | F14: 2 | G14: 2 | H14: 已备足 | I14: 与18650电池配套
B15: 11 | C15: 充电器 | D15: 18650双槽充电器 | E15: 共用1 | F15: 1 | G15: 1 | H15: 已备足（随电池购入） | I15: 两台共用
B16: 12 | C16: 供电转换 | D16: DC-DC降压模块（Mini 5V 黑板） | E16: 1 | F16: 2 | G16: 2 | H16: 已备足 | I16: 将电池电压降至5V，供核心板与舵机
... B22: 18 | C22: 板间连接 | D22: 排针/排母（2.54mm，5P/10P/4P） | E22: 若干 | F22: — | G22: 已购 | H22: 已备足 | I22: 转接板焊接与自制板接口
B24: 注：备货情况中“待购/尚缺”项对应“预算明细”表待购清单；核心板与SG90舵机已含备用件。

Sheet 订单记录
B2: 淘宝订单记录（实付款核对）
B3: 共14笔订单；“订单实付款”以订单页截图为准，是预算的唯一金额口径
B4: 序号 | C4: 下单日期 | D4: 店铺 | E4: 商品内容 | F4: 商品小计（元） | G4: 运费（元） | H4: 订单实付款（元） | I4: 备注
B5: 1 | C5: 2026-09-13 | D5: 欣薇电子企业店 | E5: 4WD金属底盘折弯板 ×2 | F5: 22.18 | G5: 3 | H5: 25.18
B6: 2 | C6: 2026-09-13 | D6: RunesKee工业旗舰店 | E6: TT马达 单轴1:48 ×8 | F6: 22.64 | G6: 0 | H6: 22.64
B7: 3 | C7: 2026-09-13 | D7: EMPERORTIGER旗舰店 | E7: 18650电池2节装+1节装（含双槽充电器） | F7: 26.92 | G7: 0 | H7: 26.92
B8: 4 | C8: 2026-09-13 | D8: 塔克创新品牌店 | E8: PS2无线手柄 ×2、麦轮套件 ×2 | F8: 154.38 | G8: 3.8 | H8: 158.19 | I8: 实付款较商品合计多0.01元，为店铺价格精度尾差
B9: 5 | C9: 2026-09-13 | D9: 深圳市优信电子科技有限公司 | E9: SG90×4、MG995×2、DRV8833×4、降压×2、杜邦线×4束、面包板、STM32×2、电池盒×2 | F9: 101.5 | G9: 0 | H9: 101.54 | I9: 实付款较商品合计多0.04元，为店铺价格精度尾差
B10: 6 | C10: 2026-09-18 | D10: 晶凝峰芯达专卖店 | E10: 单排针5P×20条、单排母1×10P×10条 | F10: 5.93 | G10: 0 | H10: 5.93
B11: 7 | C11: 2026-09-21 | D11: 乐柠萌科技企业店 | E11: 无线遥控开关（1接收器+1单键）×2 | F11: 27.6 | G11: 0 | H11: 27.6
B12: 8 | C12: 2026-09-27 | D12: 深圳市英莱利科技有限公司 | E12: 单排母1×4P ×20只 | F12: 2.7 | G12: 0 | H12: 2.7
B13: 9 | C13: 2026-10-01 | D13: 固万基官方旗舰店 | E13: M3不锈钢螺母 304 200只 | F13: 3.16 | G13: 0 | H13: 3.16
B14: 10 | C14: 2026-10-06 | D14: 佰瑞特官方旗舰店 | E14: M3/M2螺母、M3×5、M3×8、M2×8内六角螺丝（共500件） | F14: 15.24 | G14: 0 | H14: 15.24
B15: 11 | C15: 2026-10-06 | D15: 嘉耐特官方旗舰店 | E15: M3×6×0.8平垫片 100颗 | F15: 1.34 | G15: 0 | H15: 1.34
B16: 12 | C16: 2026-10-06 | D16: 佰瑞特官方旗舰店 | E16: M3×10+4六角铜柱 40个 | F16: 3.84 | G16: 0 | H16: 3.84
B17: 13 | C17: 2026-10-10 | D17: 深圳市优信电子科技有限公司 | E17: SG90×2、STM32核心板 ×1（补购） | F17: 18.11 | G17: 0 | H17: 18.11
B18: 14 | C18: 2026-10-10 | D18: 海锐新电子商城 | E18: M3×25十字盘头螺丝 100个 | F18: 1.1 | G18: 0 | H18: 1.1
D19: 合计 | F19: =SUM(F5:F18) -> 406.64 | G19: =SUM(G5:G18) -> 6.8 | H19: =SUM(H5:H18) -> 413.49

Sheet Review
B2: 数据交叉校验
B4: 校验项 | C4: 预期值 | D4: 实际值 | E4: 结果
B5: 明细表实付合计 = 订单表实付合计 | C5: =预算明细!I40 -> 413.49 | D5: =订单记录!H19 -> 413.49 | E5: =IF(ROUND(C5,2)=ROUND(D5,2),"PASS","FAIL") -> PASS
B6: 汇总页分类合计 = 明细表实付合计 | C6: =汇总!E17 -> 413.49 | D6: =预算明细!I40 -> 413.49 | E6: =IF(ROUND(C6,2)=ROUND(D6,2),"PASS","FAIL") -> PASS
B7: 预算总计 = 已实付+必购+补购 | C7: =汇总!#REF! -> #REF! | D7: =预算明细!I40+预算明细!I43+预算明细!I44+预算明细!I45 -> 436.42 | E7: =IF(ROUND(C7,2)=ROUND(D7,2),"PASS","FAIL") -> #REF!
